Workbook

Sheet Nákupní seznam
A1: Množství recepty | B1: Kontrola | C1: Množství špajz | D1: Množství celkem | E1: Typ | F1: Věc | H1: Need
F2: Cereálie a sladkosti
A3: =SUMIF(Recept!D:D,"="&F3,Recept!F:F) -> 0 | B3: FALSE | D3: =IF((A3-C3+(G3*H3))<=0,0,(A3-C3+(G3*H3))) -> 0 | E3: ks | F3: čokoláda | G3: 1 | H3: FALSE | K3: IFNA(VLOOKUP(F3,Špajz!B:D,3,FALSE),0)
A4: =SUMIF(Recept!D:D,"="&F4,Recept!F:F) -> 0 | B4: FALSE | D4: =IF((A4-C4+(G4*H4))<=0,0,(A4-C4+(G4*H4))) -> 0 | E4: gr | F4: musli | G4: 1 | H4: FALSE
A5: =SUMIF(Recept!D:D,"="&F5,Recept!F:F) -> 0 | B5: FALSE | D5: =IF((A5-C5+(G5*H5))<=0,0,(A5-C5+(G5*H5))) -> 0 | E5: ks | F5: ovesné vločky | G5: 1 | H5: FALSE
A6: =SUMIF(Recept!D:D,"="&F6,Recept!F:F) -> 0 | B6: FALSE | F6: Pečivo | H6: FALSE
A7: =SUMIF(Recept!D:D,"="&F7,Recept!F:F) -> 0 | B7: FALSE | D7: =IF((A7-C7+(G7*H7))<=0,0,(A7-C7+(G7*H7))) -> 0 | E7: ks | F7: strouhanka | G7: 1 | H7: FALSE
A8: =SUMIF(Recept!D:D,"="&F8,Recept!F:F) -> 0 | B8: FALSE | D8: =IF((A8-C8+(G8*H8))<=0,0,(A8-C8+(G8*H8))) -> 0 | E8: ks | F8: Tortilla | G8: 1 | H8: FALSE
A9: =SUMIF(Recept!D:D,"="&F9,Recept!F:F) -> 0 | B9: FALSE | F9: Ovoce & Zelenina | H9: FALSE
A10: =SUMIF(Recept!D:D,"="&F10,Recept!F:F) -> 100 | B10: TRUE | D10: =IF((A10-C10+(G10*H10))<=0,0,(A10-C10+(G10*H10))) -> 100 | E10: gr | F10: baby špenát | G10: 1 | H10: FALSE
A11: =SUMIF(Recept!D:D,"="&F11,Recept!F:F) -> 1 | B11: TRUE | D11: =IF((A11-C11+(G11*H11))<=0,0,(A11-C11+(G11*H11))) -> 1 | E11: ks | F11: banán | G11: 1 | H11: FALSE
A12: =SUMIF(Recept!D:D,"="&F12,Recept!F:F) -> 0 | B12: FALSE | D12: =IF((A12-C12+(G12*H12))<=0,0,(A12-C12+(G12*H12))) -> 0 | E12: gr | F12: brambory | G12: 1 | H12: FALSE
A13: =SUMIF(Recept!D:D,"="&F13,Recept!F:F) -> 0 | B13: FALSE | D13: =IF((A13-C13+(G13*H13))<=0,0,(A13-C13+(G13*H13))) -> 0 | E13: ks | F13: brokolice | G13: 1 | H13: FALSE
A14: =SUMIF(Recept!D:D,"="&F14,Recept!F:F) -> 1 | B14: TRUE | D14: =IF((A14-C14+(G14*H14))<=0,0,(A14-C14+(G14*H14))) -> 1 | E14: ks | F14: broskev | H14: FALSE
A15: =SUMIF(Recept!D:D,"="&F15,Recept!F:F) -> 0.5 | B15: TRUE | D15: =IF((A15-C15+(G15*H15))<=0,0,(A15-C15+(G15*H15))) -> 0.5 | E15: ks | F15: červená cibule | G15: 1 | H15: FALSE
A16: =SUMIF(Recept!D:D,"="&F16,Recept!F:F) -> 0 | B16: TRUE | D16: =IF((A16-C16+(G16*H16))<=0,0,(A16-C16+(G16*H16))) -> 0 | E16: ks | F16: česnek | G16: 1 | H16: FALSE
A17: =SUMIF(Recept!D:D,"="&F17,Recept!F:F) -> 350 | B17: TRUE | D17: =IF((A17-C17+(G17*H17))<=0,0,(A17-C17+(G17*H17))) -> 350 | E17: gr | F17: cherry rajčatka | G17: 1 | H17: FALSE
A18: =SUMIF(Recept!D:D,"="&F18,Recept!F:F) -> 4 | B18: TRUE | D18: =IF((A18-C18+(G18*H18))<=0,0,(A18-C18+(G18*H18))) -> 4 | E18: ks | F18: cibule | G18: 1 | H18: FALSE
A19: =SUMIF(Recept!D:D,"="&F19,Recept!F:F) -> 0 | B19: FALSE | D19: =IF((A19-C19+(G19*H19))<=0,0,(A19-C19+(G19*H19))) -> 0 | E19: ks | F19: citrón | G19: 1 | H19: FALSE
A20: =SUMIF(Recept!D:D,"="&F20,Recept!F:F) -> 0 | B20: FALSE | D20: =IF((A20-C20+(G20*H20))<=0,0,(A20-C20+(G20*H20))) -> 0 | E20: ks | F20: citrón | G20: 1 | H20: FALSE
A21: =SUMIF(Recept!D:D,"="&F21,Recept!F:F) -> 0 | B21: FALSE | D21: =IF((A21-C21+(G21*H21))<=0,0,(A21-C21+(G21*H21))) -> 0 | E21: gr | F21: fazolky | G21: 1 | H21: FALSE
A22: =SUMIF(Recept!D:D,"="&F22,Recept!F:F) -> 0 | B22: FALSE | D22: =IF((A22-C22+(G22*H22))<=0,0,(A22-C22+(G22*H22))) -> 0 | E22: ks | F22: hruška | G22: 1 | H22: FALSE
A23: =SUMIF(Recept!D:D,"="&F23,Recept!F:F) -> 1 | B23: TRUE | D23: =IF((A23-C23+(G23*H23))<=0,0,(A23-C23+(G23*H23))) -> 1 | E23: ks | F23: jablko | G23: 1 | H23: FALSE
A24: =SUMIF(Recept!D:D,"="&F24,Recept!F:F) -> 1.5 | B24: TRUE | D24: =IF((A24-C24+(G24*H24))<=0,0,(A24-C24+(G24*H24))) -> 1.5 | E24: ks | F24: jarní cibulka | G24: 1 | H24: FALSE
A25: =SUMIF(Recept!D:D,"="&F25,Recept!F:F) -> 3 | B25: TRUE | D25: =IF((A25-C25+(G25*H25))<=0,0,(A25-C25+(G25*H25))) -> 3 | E25: ks | F25: mrkev | G25: 1 | H25: FALSE
A26: =SUMIF(Recept!D:D,"="&F26,Recept!F:F) -> 0.5 | B26: TRUE | D26: =IF((A26-C26+(G26*H26))<=0,0,(A26-C26+(G26*H26))) -> 0.5 | E26: ks | F26: okurka | G26: 1 | H26: FALSE
... A37: =SUMIF(Recept!D:D,"="&F37,Recept!F:F) -> 150 | B37: TRUE | D37: =IF((A37-C37+(G37*H37))<=0,0,(A37-C37+(G37*H37))) -> 150 | E37: gr | F37: zelí | G37: 1 | H37: FALSE
A38: =SUMIF(Recept!D:D,"="&F38,Recept!F:F) -> 0 | B38: FALSE | F38: Maso & Uzeniny | H38: FALSE
A39: =SUMIF(Recept!D:D,"="&F39,Recept!F:F) -> 0 | B39: FALSE | D39: =IF((A39-C39+(G39*H39))<=0,0,(A39-C39+(G39*H39))) -> 0 | E39: gr | F39: bůček | G39: 1 | H39: FALSE
A40: =SUMIF(Recept!D:D,"="&F40,Recept!F:F) -> 0 | B40: FALSE | D40: =IF((A40-C40+(G40*H40))<=0,0,(A40-C40+(G40*H40))) -> 0 | E40: gr | F40: hovězí kližka | G40: 1 | H40: FALSE
A41: =SUMIF(Recept!D:D,"="&F41,Recept!F:F) -> 800 | B41: TRUE | D41: =IF((A41-C41+(G41*H41))<=0,0,(A41-C41+(G41*H41))) -> 800 | E41: gr | F41: hovězí steak | G41: 1 | H41: FALSE
A42: =SUMIF(Recept!D:D,"="&F42,Recept!F:F) -> 0 | B42: FALSE | D42: =IF((A42-C42+(G42*H42))<=0,0,(A42-C42+(G42*H42))) -> 0 | E42: gr | F42: klobása | G42: 1 | H42: FALSE
A43: =SUMIF(Recept!D:D,"="&F43,Recept!F:F) -> 0 | B43: FALSE | D43: =IF((A43-C43+(G43*H43))<=0,0,(A43-C43+(G43*H43))) -> 0 | E43: gr | F43: kosti na vývar | G43: 1 | H43: FALSE
A44: =SUMIF(Recept!D:D,"="&F44,Recept!F:F) -> 1 | B44: TRUE | D44: =IF((A44-C44+(G44*H44))<=0,0,(A44-C44+(G44*H44))) -> 1 | E44: ks | F44: kuřecí kosti | G44: 1 | H44: FALSE
A45: =SUMIF(Recept!D:D,"="&F45,Recept!F:F) -> 0 | B45: FALSE | D45: =IF((A45-C45+(G45*H45))<=0,0,(A45-C45+(G45*H45))) -> 0 | E45: gr | F45: kuřecí prsa | G45: 1 | H45: FALSE
A46: =SUMIF(Recept!D:D,"="&F46,Recept!F:F) -> 0 | B46: FALSE | D46: =IF((A46-C46+(G46*H46))<=0,0,(A46-C46+(G46*H46))) -> 0 | E46: gr | F46: losos | G46: 1 | H46: FALSE
A47: =SUMIF(Recept!D:D,"="&F47,Recept!F:F) -> 600 | B47: FALSE | D47: =IF((A47-C47+(G47*H47))<=0,0,(A47-C47+(G47*H47))) -> 600 | E47: gr | F47: mleté maso | G47: 1 | H47: FALSE
A48: =SUMIF(Recept!D:D,"="&F48,Recept!F:F) -> 0 | B48: TRUE | D48: =IF((A48-C48+(G48*H48))<=0,0,(A48-C48+(G48*H48))) -> 0 | E48: gr | F48: salám | G48: 1 | H48: FALSE
A49: =SUMIF(Recept!D:D,"="&F49,Recept!F:F) -> 0 | B49: FALSE | D49: =IF((A49-C49+(G49*H49))<=0,0,(A49-C49+(G49*H49))) -> 0 | E49: gr | F49: slanina | G49: 1 | H49: FALSE
A50: =SUMIF(Recept!D:D,"="&F50,Recept!F:F) -> 0 | B50: FALSE | D50: =IF((A50-C50+(G50*H50))<=0,0,(A50-C50+(G50*H50))) -> 0 | E50: gr | F50: steak | G50: 1 | H50: FALSE
...

Sheet Recept
A1: Výběr | B1: Recept | C1: Počet za týden | D1: Surovina 1 | E1: Množství | F1: Calc | G1: Spíž | H1: Recept
B2: Snídaně
A3: FALSE | B3: Musli s banánem | C3: 1 | D3: jogurty | E3: 1 | F3: =IF(A$3=TRUE,E3*C$3,0) -> 0 | G3: =VLOOKUP(D3,Špajz!B:D,2,FALSE) -> 0
D4: banán | E4: 1 | F4: =IF(A$3=TRUE,E4*C$3,0) -> 0 | G4: =VLOOKUP(D4,Špajz!B:D,2,FALSE) -> 0
A5: FALSE | B5: Musli s pomerančem | C5: 1 | D5: jogurty | E5: 1 | F5: =IF(A$5=TRUE,E5*C$3,0) -> 0 | G5: =VLOOKUP(D5,Špajz!B:D,2,FALSE) -> 0
D6: pomeranč | E6: 1 | F6: =IF(A$5=TRUE,E6*C$3,0) -> 0 | G6: =VLOOKUP(D6,Špajz!B:D,2,FALSE) -> 0
A7: FALSE | B7: Musli s jablkem | C7: 1 | D7: jogurty | E7: 1 | F7: =IF(A$7=TRUE,E7*C$3,0) -> 0 | G7: =VLOOKUP(D7,Špajz!B:D,2,FALSE) -> 0
D8: jablko | E8: 1 | F8: =IF(A$7=TRUE,E8*C$3,0) -> 0 | G8: =VLOOKUP(D8,Špajz!B:D,2,FALSE) -> 0
B9: Musli s švestkami | C9: 1 | D9: jogurty | E9: 1 | F9: =IF(A$9=TRUE,E9*C$3,0) -> 0 | G9: =VLOOKUP(D9,Špajz!B:D,2,FALSE) -> 0
D10: švestka | E10: 1 | F10: =IF(A$9=TRUE,E10*C$3,0) -> 0 | G10: =VLOOKUP(D10,Špajz!B:D,2,FALSE) -> 0
A11: FALSE | B11: Musli s hruškou | C11: 1 | D11: jogurty | E11: 1 | F11: =IF(A$11=TRUE,E11*C$3,0) -> 0 | G11: =VLOOKUP(D11,Špajz!B:D,2,FALSE) -> 0
D12: hruška | E12: 1 | F12: =IF(A$11=TRUE,E12*C$3,0) -> 0 | G12: =VLOOKUP(D12,Špajz!B:D,2,FALSE) -> 0
A13: FALSE | B13: Smoothie | C13: 1 | D13: mléko | E13: 200 | F13: =IF(A$13=TRUE,E13*C$13,0) -> 0 | G13: =VLOOKUP(D13,Špajz!B:D,2,FALSE) -> 0
D14: banán | E14: 1 | F14: =IF(A$13=TRUE,E14*C$13,0) -> 0 | G14: =VLOOKUP(D14,Špajz!B:D,2,FALSE) -> 0
D15: mražené ovoce | E15: 100 | F15: =IF(A$13=TRUE,E15*C$13,0) -> 0 | G15: =VLOOKUP(D15,Špajz!B:D,2,FALSE) -> 0
A16: TRUE | B16: Míchaná vejce | C16: 1 | D16: vejce | E16: 3 | F16: =IF(A$16=TRUE,E16*C$16,0) -> 3 | G16: =VLOOKUP(D16,Špajz!B:D,2,FALSE) -> 0
D17: cibule | E17: 1 | F17: =IF(A$16=TRUE,E17*C$16,0) -> 1 | G17: =VLOOKUP(D17,Špajz!B:D,2,FALSE) -> 0
D18: paprika červená | E18: 0.5 | F18: =IF(A$16=TRUE,E18*C$16,0) -> 0.5 | G18: =VLOOKUP(D18,Špajz!B:D,2,FALSE) -> #N/A
D19: okurka | E19: 0.3 | F19: =IF(A$16=TRUE,E19*C$16,0) -> 0.3 | G19: =VLOOKUP(D19,Špajz!B:D,2,FALSE) -> 0
A20: TRUE | B20: Omeleta | C20: 1 | D20: vejce | E20: 3 | F20: =IF(A$20=TRUE,E20*C$20,0) -> 3 | G20: =VLOOKUP(D20,Špajz!B:D,2,FALSE) -> 0
D21: Hrášek v konzervě | E21: 65 | F21: =IF(A$20=TRUE,E21*C$20,0) -> 65 | G21: =VLOOKUP(D21,Špajz!B:D,2,FALSE) -> 0
D22: paprika červená | E22: 0.5 | F22: =IF(A$20=TRUE,E22*C$20,0) -> 0.5 | G22: =VLOOKUP(D22,Špajz!B:D,2,FALSE) -> #N/A
A23: TRUE | B23: Ovesná kaše | C23: 1 | D23: mléko | E23: 200 | F23: =IF(A$23=TRUE,E23*C$23,0) -> 200 | G23: =VLOOKUP(D23,Špajz!B:D,2,FALSE) -> 0
D24: broskev | E24: 1 | F24: =IF(A$23=TRUE,E24*C$23,0) -> 1 | G24: =VLOOKUP(D24,Špajz!B:D,2,FALSE) -> #N/A
D25: mražené ovoce | E25: 100 | F25: =IF(A$23=TRUE,E25*C$23,0) -> 100 | G25: =VLOOKUP(D25,Špajz!B:D,2,FALSE) -> 0
A26: TRUE | B26: Chléb se šunkou | C26: 1 | D26: šunka | E26: 100 | F26: =IF(A$26=TRUE,E26*C$26,0) -> 100 | G26: =VLOOKUP(D26,Špajz!B:D,2,FALSE) -> 0
D27: cherry rajčatka | E27: 100 | F27: =IF(A$26=TRUE,E27*C$26,0) -> 100 | G27: =VLOOKUP(D27,Špajz!B:D,2,FALSE) -> 0
D28: jablko | E28: 1 | F28: =IF(A$26=TRUE,E28*C$26,0) -> 1
D29: pomazánkové máslo | E29: 1 | F29: =IF(A$26=TRUE,E29*C$26,0) -> 1 | G29: =VLOOKUP(D29,Špajz!B:D,2,FALSE) -> 0
A30: TRUE | B30: Musli | C30: 1 | D30: pomeranč | E30: 1 | F30: =IF(A$26=TRUE,E30*C$26,0) -> 1 | G30: =VLOOKUP(D30,Špajz!B:D,2,FALSE) -> 0
D31: jogurty | E31: 1 | F31: =IF(A$26=TRUE,E31*C$26,0) -> 1 | G31: =VLOOKUP(D31,Špajz!B:D,2,FALSE) -> 0
A32: TRUE | B32: Palačinka | C32: 1 | D32: celozrnná mouka | E32: 30 | F32: =IF(A$32=TRUE,E32*C$32,0) -> 30
D33: marmeláda | E33: 20 | F33: =IF(A$32=TRUE,E33*C$32,0) -> 20
D34: banán | E34: 1 | F34: =IF(A$32=TRUE,E34*C$32,0) -> 1
D35: vejce | E35: 1 | F35: =IF(A$32=TRUE,E35*C$32,0) -> 1
D36: chia semínka | E36: 10 | F36: =IF(A$32=TRUE,E36*C$32,0) -> 10
B38: Hlavní jídla
A39: FALSE | B39: Buddhovi misky | C39: 1 | D39: tofu | E39: 150 | F39: =IF(A$39=TRUE,E39*C$39,0) -> 0 | G39: =VLOOKUP(D39,Špajz!B:D,2,FALSE) -> 0
D40: jarní cibulka | E40: 0.5 | F40: =IF(A$39=TRUE,E40*C$39,0) -> 0 | G40: =VLOOKUP(D40,Špajz!B:D,2,FALSE) -> 0
D41: mrkev | E41: 1 | F41: =IF(A$39=TRUE,E41*C$39,0) -> 0 | G41: =VLOOKUP(D41,Špajz!B:D,2,FALSE) -> 0
...

Sheet Špajz
A1: Potřeba | B1: Název | C1: Množství
A2: FALSE | B2: Cereálie a sladkosti
A3: FALSE | B3: čokoláda | D3: =IF(A3,C3,0) -> 0
A4: FALSE | B4: musli | D4: =IF(A4,C4,0) -> 0
A5: FALSE | B5: ovesné vločky | D5: =IF(A5,C5,0) -> 0
A6: FALSE | B6: Pečivo | D6: =IF(A6,C6,0) -> 0
A7: FALSE | B7: strouhanka | D7: =IF(A7,C7,0) -> 0
A8: FALSE | B8: Tortilla | D8: =IF(A8,C8,0) -> 0
A9: FALSE | B9: Ovoce & Zelenina | D9: =IF(A9,C9,0) -> 0
A10: FALSE | B10: baby špenát | D10: =IF(A10,C10,0) -> 0
A11: FALSE | B11: banán | D11: =IF(A11,C11,0) -> 0
A12: FALSE | B12: brambory | D12: =IF(A12,C12,0) -> 0
A13: FALSE | B13: brokolice | D13: =IF(A13,C13,0) -> 0
A14: FALSE | B14: červená cibule | D14: =IF(A14,C14,0) -> 0
... A189: FALSE | B189: zelený čaj | D189: =IF(A189,C189,0) -> 0
